Workbook

Sheet TOTAL SCORES
A1: ='Voting Results'!$AV$1 -> Photonic - Airglow | B1: =SUM('Voting Results'!AV1:AV113) -> 63
A2: ='Voting Results'!$H$1 -> Bjporter - Nature Was The Machine | B2: =SUM('Voting Results'!H1:H154) -> 46
A3: ='Voting Results'!$J$1 -> Bzur - Expect The Unexpected | B3: =SUM('Voting Results'!J1:J153) -> 43
A4: ='Voting Results'!$P$1 -> Cycloscope - Hope | B4: =SUM('Voting Results'!P1:P148) -> 41
A5: ='Voting Results'!$AW$1 -> Rammellzee - Be Somebody | B5: =SUM('Voting Results'!AW1:AW116) -> 37
A6: ='Voting Results'!$Q$1 -> Cytosonic - Waiting For The Trickle | B6: =SUM('Voting Results'!Q1:Q149) -> 34
A7: ='Voting Results'!$T$1 -> Doc Jon - Holding A Grudge | B7: =SUM('Voting Results'!T1:T147) -> 33
A8: ='Voting Results'!$AO$1 -> Miskaseppa - Elektrotanz | B8: =SUM('Voting Results'!AO1:AO127) -> 31
A9: ='Voting Results'!$AF$1 -> Irion Da Ronin - Innocent Memories | B9: =SUM('Voting Results'!AF1:AF137) -> 30
A10: ='Voting Results'!$Z$1 -> Evo2slo - Escape Pod | B10: =SUM('Voting Results'!Z1:Z144) -> 29
A11: ='Voting Results'!$BE$1 -> Skyzone - I Need Space | B11: =SUM('Voting Results'!BE1:BE119) -> 29
A12: ='Voting Results'!$AG$1 -> Kimik - Slowmotiodolski | B12: =SUM('Voting Results'!AG1:AG139) -> 28
A13: ='Voting Results'!$BO$1 -> Z.Prime - The Living | B13: =SUM('Voting Results'!BO1:BO121) -> 28
A14: ='Voting Results'!$AC$1 -> Harthstein - The Last Enchantress | B14: =SUM('Voting Results'!AC1:AC145) -> 27
A15: ='Voting Results'!$AP$1 -> Moka Disco Express - Discharged | B15: =SUM('Voting Results'!AP1:AP133) -> 27
A16: ='Voting Results'!$V$1 -> Dzah - Watermusic | B16: =SUM('Voting Results'!V1:V154) -> 26
A17: ='Voting Results'!$AJ$1 -> Kraftraum - Rotation 14 | B17: =SUM('Voting Results'!AJ1:AJ141) -> 23
A18: ='Voting Results'!$BG$1 -> Sonnydeluxe - Fields Of Glory - The Last Battle Of General Podolski | B18: =SUM('Voting Results'!BG1:BG126) -> 21
A19: ='Voting Results'!$W$1 -> E@rs - Earth Shaker | B19: =SUM('Voting Results'!W1:W156) -> 19
A20: ='Voting Results'!$BB$1 -> Saltline - Lukasz | B20: =SUM('Voting Results'!X1:X156) -> 18
A21: ='Voting Results'!$X$1 -> Eauson Podolski | B21: =SUM('Voting Results'!BB1:BB129) -> 18
A22: ='Voting Results'!$I$1 -> Broad Halls Of Yeast - Mimas Orbital Solutions | B22: =SUM('Voting Results'!I1:I173) -> 16
A23: ='Voting Results'!$AA$1 -> Examigan - Relativity | B23: =SUM('Voting Results'!AA1:AA156) -> 15
A24: ='Voting Results'!$BF$1 -> Solidtrax - The Dreamer Awakes | B24: =SUM('Voting Results'!BF1:BF132) -> 13
A25: ='Voting Results'!$AB$1 -> Gamma-UT - 235 | B25: =SUM('Voting Results'!AB1:AB157) -> 12
A26: ='Voting Results'!$BA$1 -> Ruedirena - Incident At Fhloston Paradise | B26: =SUM('Voting Results'!AT1:AT140) -> 11
A27: ='Voting Results'!$AU$1 -> Pedalsteeldrummer - Artoo Detoo! It's You! | B27: =SUM('Voting Results'!AU1:AU140) -> 11
A28: ='Voting Results'!$AT$1 -> Ontrackp - Podostinato 2 | B28: =SUM('Voting Results'!BA1:BA136) -> 11
A29: ='Voting Results'!$K$1 -> Carl_saved - Walking With My Saviour | B29: =SUM('Voting Results'!K1:K178) -> 10
A30: ='Voting Results'!$Y$1 -> Entagled Noise - Remote Island | B30: =SUM('Voting Results'!Y1:Y165) -> 9
A31: ='Voting Results'!$D$1 -> Besh - Pd8 | B31: =SUM('Voting Results'!D1:D187) -> 8
A32: ='Voting Results'!$AX$1 -> Ricler - Like The Same Old Tune | B32: =SUM('Voting Results'!AX1:AX142) -> 8
A33: ='Voting Results'!$BN$1 -> Yeager - Alan Was Right | B33: =SUM('Voting Results'!BN1:BN141) -> 8
A34: ='Voting Results'!$C$1 -> Abovethoughts - Music For Pods | B34: =SUM('Voting Results'!C1:C191) -> 7
A35: ='Voting Results'!$AQ$1 -> Mushy Mushy - Pole Dancing On Skis | B35: =SUM('Voting Results'!AQ1:AQ152) -> 7
A36: ='Voting Results'!$E$1 -> Besh - Podolski Osc | B36: =SUM('Voting Results'!E1:E191) -> 6
A37: ='Voting Results'!$O$1 -> Ctx - Smells Cheezy In The Changing Room | B37: =SUM('Voting Results'!O1:O182) -> 6
A38: ='Voting Results'!$AI$1 -> Kraftraum - Rotation 13 (Escape From Orbit) | B38: =SUM('Voting Results'!AI1:AI163) -> 6
A39: ='Voting Results'!$AY$1 -> Rotobam - Frog Walk | B39: =SUM('Voting Results'!AY1:AY148) -> 6
A40: ='Voting Results'!$R$1 -> Davias - Podol Not Skilled | B40: =SUM('Voting Results'!R1:R182) -> 5
...

Sheet Voting Results
A1: Timestamp | B1: Voter Name (your KVR nick) | C1: Abovethoughts - Music For Pods | D1: Besh - Pd8 | E1: Besh - Podolski Osc | F1: Bh9090 - Losing The Loudness War | G1: Bh9090 - The Veiled Path | H1: Bjporter - Nature Was The Machine | I1: Broad Halls Of Yeast - Mimas Orbital Solutions | J1: Bzur - Expect The Unexpected | K1: Carl_saved - Walking With My Saviour | L1: Cat Gordon - July, Open Your Eyes | M1: Clarago - Podology 1 | N1: Clarago Dubski | O1: Ctx - Smells Cheezy In The Changing Room | P1: Cycloscope - Hope | Q1: Cytosonic - Waiting For The Trickle | R1: Davias - Podol Not Skilled | S1: Deadreactor - Clockwise | T1: Doc Jon - Holding A Grudge | U1: Dwringer - Ex Machina | V1: Dzah - Watermusic | W1: E@rs - Earth Shaker | X1: Eauson Podolski | Y1: Entagled Noise - Remote Island | Z1: Evo2slo - Escape Pod | AA1: Examigan - Relativity | AB1: Gamma-UT - 235 | AC1: Harthstein - The Last Enchantress | AD1: Hienergy - Thematische Arbeit Mit Podolski | AE1: Idfpower - Poddity | AF1: Irion Da Ronin - Innocent Memories | AG1: Kimik - Slowmotiodolski | AH1: Kondarivan - Earthrise | AI1: Kraftraum - Rotation 13 (Escape From Orbit) | AJ1: Kraftraum - Rotation 14 | AK1: Liquidgreg - Black Rain | AL1: Liquidgreg - Prometheus Rising | AM1: Mike777 - City Night | AN1: Mike777 - It Was Seen Over Fields And Lakes | AO1: Miskaseppa - Elektrotanz | AP1: Moka Disco Express - Discharged | AQ1: Mushy Mushy - Pole Dancing On Skis | AR1: Nightpolymath - Mercury | AS1: Nikp2000 - Ghosties | AT1: Ontrackp - Podostinato 2 | AU1: Pedalsteeldrummer - Artoo Detoo! It's You! | AV1: Photonic - Airglow | AW1: Rammellzee - Be Somebody | AX1: Ricler - Like The Same Old Tune | AY1: Rotobam - Frog Walk | AZ1: Ruedirena - Black Hole Gold | BA1: Ruedirena - Incident At Fhloston Paradise | BB1: Saltline - Lukasz | BC1: Simonhans73 - Deep Feeling | BD1: Sirken - Podolski's Revenge | BE1: Skyzone - I Need Space | BF1: Solidtrax - The Dreamer Awakes | BG1: Sonnydeluxe - Fields Of Glory - The Last Battle Of General Podolski | BH1: Sovaroz_x0081_m - Hypercube III | BI1: Sovaroz_x0081_m - Hypercube III-S | BJ1: Sovaroz_x0081_m - Temporal Shift | BK1: Toddhisattva - Doll Sky | BL1: Tonedef71 - The Night Is Dark And Full Of Terrors | BM1: Vasiliset.Ma - A49 | BN1: Yeager - Alan Was Right | BO1: Z.Prime - The Living
A2: 41427.316 | B2: ghettosynth | Q2: 4 | W2: 2 | AB2: 3 | AS2: 1 | AW2: 5
A3: 41427.44 | B3: Kondarivan | J3: 5 | V3: 4 | AF3: 1 | AV3: 3 | BE3: 2
A4: 41427.595 | B4: liquidgreg | H4: 5 | AO4: 3 | AQ4: 4 | AV4: 2 | BG4: 1
A5: 41427.759 | B5: Carl-saved | AO5: 1 | AP5: 2 | AV5: 5 | AY5: 3 | BO5: 4
A6: 41427.761 | B6: idfpower | Z6: 5 | AA6: 4 | AI6: 1 | BF6: 2 | BN6: 3
A7: 41427.768 | B7: simonhans73 | M7: 3 | X7: 4 | AA7: 1 | AO7: 5 | AU7: 2
A8: 41427.795 | B8: Examigan | C8: 2 | T8: 3 | AE8: 5 | AI8: 4 | AP8: 1
A9: 41428.345 | B9: Nightpolymath | H9: 1 | I9: 5 | J9: 2 | Y9: 4 | BH9: 3
A10: 41428.36 | B10: Entangled Noise | I10: 4 | X10: 5 | AF10: 2 | AI10: 1 | BN10: 3
A11: 41428.42 | B11: Cat Gordon | K11: 4 | AO11: 2 | AV11: 1 | AX11: 5 | BO11: 3
A12: 41429.3 | B12: Sovarozum | X12: 3 | AC12: 1 | AS12: 1 | AV12: 4 | BA12: 1 | BE12: 5
A13: 41429.671 | B13: kimik | O13: 3 | P13: 4 | V13: 2 | AV13: 5 | BA13: 1
A14: 41429.888 | B14: Photonic | H14: 1 | T14: 5 | AC14: 2 | BE14: 3 | BG14: 4
A15: 41430.928 | B15: RuediRena | J15: 5 | Q15: 1 | T15: 2 | AJ15: 4 | BE15: 3
A16: 41431.061 | B16: Mike777 | F16: 1 | AF16: 3 | AG16: 4 | AV16: 2 | BG16: 5
A17: 41431.173 | B17: Diego_C | Q17: 5 | T17: 4 | AJ17: 3 | AQ17: 1 | BB17: 2
A18: 41431.375 | B18: cytoSonic | E18: 4 | L18: 3 | W18: 5 | AT18: 2 | BJ18: 1
A19: 41431.41 | B19: ricler | D19: 4 | V19: 5 | AT19: 3 | BD19: 1 | BG19: 2
A20: 41431.747 | B20: z.prime | P20: 5 | AJ20: 4 | AO20: 1 | AW20: 3 | BE20: 2
A21: 41431.888 | B21: Irion Da Ronin | H21: 1 | P21: 3 | AC21: 4 | AG21: 2 | AV21: 5
A22: 41432.178 | B22: ontrackp | Q22: 5 | Z22: 3 | AA22: 2 | AP22: 4 | BJ22: 1
A23: 41432.531 | B23: ctx | J23: 4 | Z23: 1 | AV23: 5 | BA23: 3 | BK23: 2
A24: 41433.146 | B24: kraftraum | J24: 5 | T24: 1 | X24: 3 | AG24: 4 | BE24: 2
A25: 41433.669 | B25: deadReactor | Q25: 1 | W25: 5 | AF25: 3 | AJ25: 4 | AL25: 2
A26: 41434.322 | B26: tonedef71 | Z26: 5 | AG26: 3 | AQ26: 2 | AV26: 4 | BF26: 1
A27: 41434.375 | B27: saltline | Q27: 5 | V27: 3 | AW27: 4 | AY27: 2 | BF27: 1
A28: 41434.518 | B28: ClaRago | U28: 2 | V28: 4 | W28: 5 | AW28: 3 | BA28: 1
A29: 41434.919 | B29: tomtoo | V29: 4 | AC29: 2 | AO29: 5 | AT29: 3 | BL29: 1
A30: 41434.944 | B30: bzur | AF30: 4 | AU30: 1 | BB30: 3 | BE30: 5 | BF30: 2
A31: 41435 | B31: Doc Jon | AC31: 4 | AF31: 3 | AH31: 1 | AO31: 5 | AV31: 2
A32: 41435.324 | B32: sunhome | C32: 5 | H32: 4 | J32: 3 | R32: 2 | Z32: 1
A33: 41435.406 | B33: solidtrax | H33: 4 | P33: 5 | BC33: 1 | BG33: 3 | BO33: 2
A34: 41435.778 | B34: HiEnergy | H34: 4 | K34: 2 | AC34: 5 | AO34: 3 | AV34: 1
A35: 41436.494 | B35: besh | P35: 2 | Y35: 5 | AG35: 3 | BB35: 4 | BD35: 1
A36: 41437.101 | B36: bjporter | I36: 2 | P36: 1 | T36: 5 | AM36: 4 | AV36: 3
A37: 41437.236 | B37: Davias | P37: 5 | AU37: 4 | AV37: 2 | AY37: 1 | BO37: 3
A38: 41437.564 | B38: miskaseppa | AF38: 2 | AG38: 5 | AJ38: 4 | BE38: 3 | BO38: 1
A39: 41438.191 | B39: nikp2000 | Q39: 3 | T39: 2 | Z39: 4 | AM39: 1 | BA39: 5
A40: 41438.262 | B40: abovethoughts | D40: 4 | E40: 2 | H40: 5 | O40: 3 | X40: 1
...
