Workbook

Sheet Voting Results
A1: Timestamp | B1: Voter name (KVR nick) | C1: AdagioCm - Eilistraee (The Dance of the Dark Maiden) | D1: Angelremington - simple melody | E1: Angelremington - triple cheezer | F1: bharris22 - Muscovite's Lament | G1: bzur - Unconventionally | H1: Cactoos - A Better Tomorrow - intro | I1: CapDan - Changes | J1: ClaRago - Panacotta Army | K1: ClaRago - Play a Saw | L1: ClaRago-Cocheese 's Rain Dance ( It's Gouda Be the Chief) | M1: Dimtsak - Watch the thorns | N1: Distorque - Radix | O1: Doc Jon - Breaking the Code | P1: Dzah - ConterPHarmonic1 | Q1: e@rs - Human No More | R1: evo2slo - Dreamtime | S1: Farlukar - Gazelle | T1: Irion Da Ronin - Na Die Reën | U1: Jasinski - Just One More | V1: Jasinski - Why Do We Keep Doing What We Do | W1: Kraftraum - Rotation 10 (Voyager) | X1: Kraftraum - Rotation 9 | Y1: liquidgreg - Endeavour | Z1: Loris D Solic - Tensile strength | AA1: marks-a-whybikky - Feed for a film (1) | AB1: marks-a-whybikky - Sandy Island (SouthPacific) | AC1: marks-a-whybikky - Search, find and loose | AD1: Nahkaorava - Serious Hypolactasia | AE1: Nikp2000 - Stinky | AF1: pedalsteeldrummer - We Come In Peace | AG1: Photonic - BrieAmplifier | AH1: QuadrupleA - Cheese Symphony | AI1: QuadrupleA - Twitchy Robot v2 | AJ1: Quaoar - Vintage Cheese | AK1: Ricler - Space cheese | AL1: Ricler - The Cheese Shop | AM1: Rob West - Rennet | AN1: RuediRena - Black Flash Dub | AO1: RuediRena - El Cheapo Jingle | AP1: RuediRena - RdcttMxJngl | AQ1: Shadows of Birds - Crayons and Dodos | AR1: Skyzone - Brothers and Sisters | AS1: Skyzone - Our crowded world | AT1: Skyzone - The end of the universe | AU1: Skyzone - Voices of faith | AV1: Solidtrax - Black Cheese | AW1: Thrax - Sliced and Diced | AX1: Yeager - Smile ! | AY1: z.prime - Under the Australian Moon [Redux] | AZ1: zgraja - Triple Impact
A2: 41245.49 | B2: dimtsak | H2: 2 | R2: 4 | T2: 1 | AG2: 5 | AH2: 3
A3: 41245.88 | B3: ClaRago | G3: 2 | V3: 1 | AB3: 5 | AF3: 3 | AQ3: 4
A4: 41247.437 | B4: Robert West | O4: 3 | AF4: 1 | AI4: 5 | AW4: 4 | AX4: 2
A5: 41248.459 | B5: ShadowsofBirds | W5: 1 | AC5: 3 | AF5: 4 | AH5: 5 | AM5: 2
A6: 41248.874 | B6: marks-a-whybikky | K6: 1 | Q6: 3 | W6: 5 | Z6: 2 | AF6: 4
A7: 41251.846 | B7: QuadrupleA | T7: 4 | V7: 5 | AB7: 1 | AS7: 2 | AX7: 3
A8: 41251.847 | B8: zgraja | V8: 4 | AD8: 3 | AG8: 5 | AS8: 1 | AW8: 2
A9: 41251.848 | B9: photonic | O9: 4 | T9: 1 | AD9: 5 | AF9: 2 | AI9: 3
A10: 41251.849 | B10: kraftraum | AF10: 1 | AG10: 3 | AS10: 5 | AV10: 2 | AW10: 4
A11: 41252.897 | B11: solidtrax | T11: 2 | U11: 5 | V11: 4 | AG11: 3 | AI11: 1
A12: 41252.898 | B12: nikp2000 | V12: 5 | X12: 1 | AH12: 2 | AQ12: 4 | AX12: 3
A13: 41252.899 | B13: pedalsteeldrummer | T13: 1 | AB13: 5 | AI13: 2 | AQ13: 3 | AR13: 4
A14: 41253.575 | B14: liquidgreg | D14: 5 | T14: 1 | AG14: 4 | AS14: 2 | AW14: 3
A15: 41254.67 | B15: loris16148 | H15: 1 | T15: 5 | V15: 4 | AG15: 3 | AI15: 2
A16: 41255.644 | B16: DzAH | H16: 2 | M16: 5 | R16: 3 | AD16: 4 | AZ16: 1
A17: 41256.53 | B17: Doc Jon | R17: 5 | T17: 3 | AG17: 2 | AH17: 4 | AV17: 1
A18: 41256.538 | B18: nahkaorava | V18: 4 | AG18: 5 | AH18: 3 | AI18: 2 | AX18: 1
A19: 41256.934 | B19: Thrax | H19: 5 | T19: 1 | V19: 4 | AD19: 3 | AY19: 2
A20: 41257.526 | B20: ricler | S20: 3 | T20: 2 | V20: 4 | AD20: 5 | AF20: 1
A21: 41257.57 | B21: markheath | H21: 4 | T21: 2 | AD21: 1 | AG21: 5 | AY21: 3
A22: 41258.837 | B22: farlukar | Q22: 3 | U22: 1 | AA22: 4 | AF22: 5 | AN22: 2
A23: 41258.837 | B23: e@rs | H23: 3 | R23: 4 | V23: 2 | X23: 1 | AV23: 5
A24: 41258.838 | B24: U-o | H24: 5 | T24: 3 | V24: 2 | AH24: 1 | AV24: 4
A25: 41258.838 | B25: SKYZONE | W25: 5 | Y25: 2 | AF25: 4 | AI25: 3 | AZ25: 1
A26: 41258.839 | B26: Yeager | V26: 2 | AG26: 4 | AI26: 1 | AV26: 5 | AY26: 3
A27: 41258.842 | B27: bftucker | V27: 5 | AA27: 2 | AD27: 3 | AG27: 1 | AV27: 4
A28: 41258.931 | B28: evo2slo | K28: 5 | Q28: 1 | T28: 4 | V28: 2 | AG28: 3
A29: 41258.931 | B29: IrionDaRonin | H29: 3 | R29: 2 | W29: 1 | AG29: 5 | AY29: 4
A30: 41259.492 | B30: z.prime | H30: 3 | R30: 5 | T30: 4 | V30: 1 | AG30: 2
A31: 41259.493 | B31: Aiynzahev | H31: 5 | Q31: 2 | T31: 3 | AI31: 1 | AV31: 4
A32: 41259.493 | B32: jasinski | H32: 2 | T32: 3 | AG32: 5 | AV32: 1 | AY32: 4
A33: 41259.494 | B33: cactoos_dahoo | R33: 2 | T33: 5 | U33: 4 | AG33: 3 | AV33: 1

Sheet TOTAL SCORES
A1: ='Voting Results'!$AG$1 -> Photonic - BrieAmplifier | B1: =SUM('Voting Results'!AG1:AG101) -> 58
A2: ='Voting Results'!$V$1 -> Jasinski - Why Do We Keep Doing What We Do | B2: =SUM('Voting Results'!V1:V113) -> 49
A3: ='Voting Results'!$T$1 -> Irion Da Ronin - Na Die Reën | B3: =SUM('Voting Results'!T1:T116) -> 45
A4: ='Voting Results'!$H$1 -> Cactoos - A Better Tomorrow - intro | B4: =SUM('Voting Results'!H1:H128) -> 35
A5: ='Voting Results'!$AV$1 -> Solidtrax - Black Cheese | B5: =SUM('Voting Results'!AV1:AV90) -> 27
A6: ='Voting Results'!$R$1 -> evo2slo - Dreamtime | B6: =SUM('Voting Results'!R1:R120) -> 25
A7: ='Voting Results'!$AF$1 -> pedalsteeldrummer - We Come In Peace | B7: =SUM('Voting Results'!AF1:AF108) -> 25
A8: ='Voting Results'!$AD$1 -> Nahkaorava - Serious Hypolactasia | B8: =SUM('Voting Results'!AD1:AD111) -> 24
A9: ='Voting Results'!$AI$1 -> QuadrupleA - Twitchy Robot v2 | B9: =SUM('Voting Results'!AI1:AI107) -> 20
A10: ='Voting Results'!$AH$1 -> QuadrupleA - Cheese Symphony | B10: =SUM('Voting Results'!AH1:AH109) -> 18
A11: ='Voting Results'!$AY$1 -> z.prime - Under the Australian Moon [Redux] | B11: =SUM('Voting Results'!AY1:AY93) -> 16
A12: ='Voting Results'!$AW$1 -> Thrax - Sliced and Diced | B12: =SUM('Voting Results'!AW1:AW96) -> 13
A13: ='Voting Results'!$W$1 -> Kraftraum - Rotation 10 (Voyager) | B13: =SUM('Voting Results'!W1:W123) -> 12
A14: ='Voting Results'!$AB$1 -> marks-a-whybikky - Sandy Island (SouthPacific) | B14: =SUM('Voting Results'!AB1:AB119) -> 11
A15: ='Voting Results'!$AQ$1 -> Shadows of Birds - Crayons and Dodos | B15: =SUM('Voting Results'!AQ1:AQ105) -> 11
A16: ='Voting Results'!$U$1 -> Jasinski - Just One More | B16: =SUM('Voting Results'!U1:U128) -> 10
A17: ='Voting Results'!$AS$1 -> Skyzone - Our crowded world | B17: =SUM('Voting Results'!AS1:AS105) -> 10
A18: ='Voting Results'!$Q$1 -> e@rs - Human No More | B18: =SUM('Voting Results'!Q1:Q133) -> 9
A19: ='Voting Results'!$AX$1 -> Yeager - Smile ! | B19: =SUM('Voting Results'!AX1:AX102) -> 9
A20: ='Voting Results'!$O$1 -> Doc Jon - Breaking the Code | B20: =SUM('Voting Results'!O1:O137) -> 7
A21: ='Voting Results'!$K$1 -> ClaRago - Play a Saw | B21: =SUM('Voting Results'!K1:K142) -> 6
A22: ='Voting Results'!$AA$1 -> marks-a-whybikky - Feed for a film (1) | B22: =SUM('Voting Results'!AA1:AA128) -> 6
A23: ='Voting Results'!$D$1 -> Angelremington - simple melody | B23: =SUM('Voting Results'!D1:D151) -> 5
A24: ='Voting Results'!$M$1 -> Dimtsak - Watch the thorns | B24: =SUM('Voting Results'!M1:M143) -> 5
A25: ='Voting Results'!$AR$1 -> Skyzone - Brothers and Sisters | B25: =SUM('Voting Results'!AR1:AR114) -> 4
A26: ='Voting Results'!$AC$1 -> marks-a-whybikky - Search, find and loose | B26: =SUM('Voting Results'!AC1:AC130) -> 3
A27: ='Voting Results'!$S$1 -> Farlukar - Gazelle | B27: =SUM('Voting Results'!S1:S26) -> 3
A28: ='Voting Results'!$G$1 -> bzur - Unconventionally | B28: =SUM('Voting Results'!G2:G153) -> 2
A29: ='Voting Results'!$X$1 -> Kraftraum - Rotation 9 | B29: =SUM('Voting Results'!X2:X138) -> 2
A30: ='Voting Results'!$Y$1 -> liquidgreg - Endeavour | B30: =SUM('Voting Results'!Y2:Y138) -> 2
A31: ='Voting Results'!$Z$1 -> Loris D Solic - Tensile strength | B31: =SUM('Voting Results'!Z2:Z138) -> 2
A32: ='Voting Results'!$AM$1 -> Rob West - Rennet | B32: =SUM('Voting Results'!AM1:AM126) -> 2
A33: ='Voting Results'!$AN$1 -> RuediRena - Black Flash Dub | B33: =SUM('Voting Results'!AN1:AN126) -> 2
A34: ='Voting Results'!$AZ$1 -> zgraja - Triple Impact | B34: =SUM('Voting Results'!AZ1:AZ115) -> 2
A35: ='Voting Results'!$C$1 -> AdagioCm - Eilistraee (The Dance of the Dark Maiden) | B35: =SUM('Voting Results'!C2:C165) -> 0
A36: ='Voting Results'!$E$1 -> Angelremington - triple cheezer | B36: =SUM('Voting Results'!E1:E163) -> 0
A37: ='Voting Results'!$F$1 -> bharris22 - Muscovite's Lament | B37: =SUM('Voting Results'!F1:F163) -> 0
A38: ='Voting Results'!$I$1 -> CapDan - Changes | B38: =SUM('Voting Results'!I1:I161) -> 0
A39: ='Voting Results'!$J$1 -> ClaRago - Panacotta Army | B39: =SUM('Voting Results'!J1:J161) -> 0
A40: ='Voting Results'!$L$1 -> ClaRago-Cocheese 's Rain Dance ( It's Gouda Be the Chief) | B40: =SUM('Voting Results'!L1:L160) -> 0
...
