Workbook

Sheet TOTAL SCORES
A1: ='Voting Results'!$AQ$1 -> Z.Prime - Memories | B1: =SUM('Voting Results'!AQ1:AQ42) -> 165
A2: ='Voting Results'!$Q$1 -> Irion Da Ronin - Night Walker | B2: =SUM('Voting Results'!Q1:Q42) -> 164
A3: ='Voting Results'!$E$1 -> Bjporter - Parachuting Down To A Supersaw Welcome | B3: =SUM('Voting Results'!E1:E42) -> 160
A4: ='Voting Results'!$H$1 -> Bzur - Simple And Clean | B4: =SUM('Voting Results'!H1:H42) -> 155
A5: ='Voting Results'!$Y$1 -> Photonic - Sound Of Summer Nights | B5: =SUM('Voting Results'!Y1:Y42) -> 152
A6: ='Voting Results'!$AL$1 -> Stunkit - Spacefield | B6: =SUM('Voting Results'!AL1:AL42) -> 152
A7: ='Voting Results'!$AH$1 -> Skyzone - The Albatross Is Eating Plastic | B7: =SUM('Voting Results'!AH1:AH42) -> 148
A8: ='Voting Results'!$AP$1 -> Yeager - Paraphrase | B8: =SUM('Voting Results'!AP1:AP42) -> 146
A9: ='Voting Results'!$T$1 -> Kullervo - Stone Alley | B9: =SUM('Voting Results'!O1:O42) -> 143
A10: ='Voting Results'!$O$1 -> Evo2slo - Summer Lover | B10: =SUM('Voting Results'!T1:T42) -> 143
A11: ='Voting Results'!$I$1 -> Carl Saved - Power, Beauty And Madness | B11: =SUM('Voting Results'!R1:R42) -> 139
A12: ='Voting Results'!$R$1 -> Kondarivan - Heat Shield | B12: =SUM('Voting Results'!I1:I42) -> 139
A13: ='Voting Results'!$S$1 -> Kraftraum - Rotation 15 | B13: =SUM('Voting Results'!S1:S43) -> 136
A14: ='Voting Results'!$AC$1 -> Saltline - Minas Gerais | B14: =SUM('Voting Results'!AC2:AC42) -> 135
A15: ='Voting Results'!$K$1 -> Ctx - Behind The Curtain | B15: =SUM('Voting Results'!K1:K42) -> 135
A16: ='Voting Results'!$X$1 -> Pedalsteeldrummer - Eos | B16: =SUM('Voting Results'!X1:X42) -> 131
A17: ='Voting Results'!$G$1 -> Broad Halls Of Yeast - Forlorn Encystment | B17: =SUM('Voting Results'!G1:G42) -> 130
A18: ='Voting Results'!$F$1 -> Bjulin - Expedition | B18: =SUM('Voting Results'!F1:F42) -> 126
A19: ='Voting Results'!$AG$1 -> Sjmmusic - Sheep Lullaby | B19: =SUM('Voting Results'!AG1:AG42) -> 123
A20: ='Voting Results'!$V$1 -> Mushy Mushy - 60% Crusty | B20: =SUM('Voting Results'!V1:V42) -> 122
A21: ='Voting Results'!$L$1 -> Davias - Kvr Osc 53 - Smi -Sft | B21: =SUM('Voting Results'!L1:L42) -> 121
A22: ='Voting Results'!$M$1 -> Dzah - Rainforest | B22: =SUM('Voting Results'!M1:M42) -> 121
A23: ='Voting Results'!$AD$1 -> Saukar30 - Breaking Through The Pain | B23: =SUM('Voting Results'!AD1:AD42) -> 119
A24: ='Voting Results'!$N$1 -> E@rs - The Blade That Shaved Chuck Norris | B24: =SUM('Voting Results'!N1:N42) -> 118
A25: ='Voting Results'!$U$1 -> Lunatech - Space Phunk Cyber Jazz Session At The Rift Cafe | B25: =SUM('Voting Results'!U1:U42) -> 114
A26: ='Voting Results'!$AN$1 -> Vdx - Falling Stars | B26: =SUM('Voting Results'!AF1:AF42) -> 111
A27: ='Voting Results'!$AF$1 -> Simonhans73- Together (3. Ver) | B27: =SUM('Voting Results'!AN1:AN42) -> 111
A28: ='Voting Results'!$P$1 -> Idfpower - Binary Code | B28: =SUM('Voting Results'!P1:P42) -> 108
A29: ='Voting Results'!$Z$1 -> Quadruplea - Aftermath | B29: =SUM('Voting Results'!Z1:Z42) -> 107
A30: ='Voting Results'!$AM$1 -> Tonedef71 - Ambush At The Oasis | B30: =SUM('Voting Results'!AK1:AK42) -> 106
A31: ='Voting Results'!$AK$1 -> Spectralbee - One Gun | B31: =SUM('Voting Results'!AM1:AM42) -> 106
A32: ='Voting Results'!$AB$1 -> Ruedirena - Suction V8 | B32: =SUM('Voting Results'!AB1:AB42) -> 104
A33: ='Voting Results'!$AJ$1 -> Sovaroz_x0081_m - Journey Through A Panicked Heart | B33: =SUM('Voting Results'!AJ1:AJ42) -> 100
A34: ='Voting Results'!$D$1 -> Ballacr75 - Psyko | B34: =SUM('Voting Results'!AI1:AI42) -> 98
A35: ='Voting Results'!$AI$1 -> Sonnydeluxe - Monaco | B35: =SUM('Voting Results'!D1:D42) -> 98
A36: ='Voting Results'!$AE$1 -> Simonhans73 - Shake It (Ver. 3) | B36: =SUM('Voting Results'!AE1:AE42) -> 96
A37: ='Voting Results'!$AO$1 -> Wakkadude - Saxonite | B37: =SUM('Voting Results'!AO1:AO42) -> 95
A38: ='Voting Results'!$W$1 -> Nikp2000 - There Will Be Pie | B38: =SUM('Voting Results'!AA1:AA42) -> 94
A39: ='Voting Results'!$AA$1 -> Ricler - On The Road Back To Home | B39: =SUM('Voting Results'!W1:W42) -> 94
A40: ='Voting Results'!$J$1 -> Clarago - Nag | B40: =SUM('Voting Results'!J1:J42) -> 89
...

Sheet Voting Results
A1: Timestamp | B1: Voter Name | C1: Abovethoughts - To Us.Wavabovethoughts - To Us [Robot Remix] | D1: Ballacr75 - Psyko | E1: Bjporter - Parachuting Down To A Supersaw Welcome | F1: Bjulin - Expedition | G1: Broad Halls Of Yeast - Forlorn Encystment | H1: Bzur - Simple And Clean | I1: Carl Saved - Power, Beauty And Madness | J1: Clarago - Nag | K1: Ctx - Behind The Curtain | L1: Davias - Kvr Osc 53 - Smi -Sft | M1: Dzah - Rainforest | N1: E@rs - The Blade That Shaved Chuck Norris | O1: Evo2slo - Summer Lover | P1: Idfpower - Binary Code | Q1: Irion Da Ronin - Night Walker | R1: Kondarivan - Heat Shield | S1: Kraftraum - Rotation 15 | T1: Kullervo - Stone Alley | U1: Lunatech - Space Phunk Cyber Jazz Session At The Rift Cafe | V1: Mushy Mushy - 60% Crusty | W1: Nikp2000 - There Will Be Pie | X1: Pedalsteeldrummer - Eos | Y1: Photonic - Sound Of Summer Nights | Z1: Quadruplea - Aftermath | AA1: Ricler - On The Road Back To Home | AB1: Ruedirena - Suction V8 | AC1: Saltline - Minas Gerais | AD1: Saukar30 - Breaking Through The Pain | AE1: Simonhans73 - Shake It (Ver. 3) | AF1: Simonhans73- Together (3. Ver) | AG1: Sjmmusic - Sheep Lullaby | AH1: Skyzone - The Albatross Is Eating Plastic | AI1: Sonnydeluxe - Monaco | AJ1: Sovaroz_x0081_m - Journey Through A Panicked Heart | AK1: Spectralbee - One Gun | AL1: Stunkit - Spacefield | AM1: Tonedef71 - Ambush At The Oasis | AN1: Vdx - Falling Stars | AO1: Wakkadude - Saxonite | AP1: Yeager - Paraphrase | AQ1: Z.Prime - Memories
A2: 41457.033 | B2: sunhome | C2: 4 | D2: 2 | E2: 3 | F2: 2 | G2: 2 | H2: 3 | I2: 4 | J2: 2 | K2: 3 | L2: 4 | M2: 3 | N2: 3 | O2: 4 | P2: 4 | Q2: 3 | R2: 4 | S2: 5 | T2: 3 | U2: 3 | V2: 5 | W2: 3 | X2: 4 | Y2: 3 | Z2: 3 | AA2: 2 | AB2: 4 | AC2: 3 | AD2: 3 | AE2: 2 | AF2: 3 | AG2: 3 | AH2: 4 | AI2: 2 | AJ2: 4 | AK2: 3 | AL2: 5 | AM2: 2 | AN2: 3 | AO2: 2 | AP2: 4 | AQ2: 4
A3: 41457.486 | B3: kinkajou | C3: 2 | D3: 3 | E3: 5 | F3: 4 | G3: 3 | H3: 2 | I3: 3 | J3: 4 | K3: 4 | L3: 3 | M3: 2 | N3: 2 | O3: 3 | P3: 4 | Q3: 4 | R3: 3 | S3: 2 | T3: 3 | U3: 4 | V3: 3 | W3: 2 | X3: 3 | Y3: 4 | Z3: 3 | AA3: 3 | AB3: 2 | AC3: 4 | AD3: 2 | AE3: 2 | AF3: 2 | AG3: 3 | AH3: 4 | AI3: 4 | AJ3: 3 | AK3: 1 | AL3: 3 | AM3: 3 | AN3: 4 | AO3: 2 | AP3: 3 | AQ3: 2
A4: 41457.597 | B4: Kullervo | C4: 2 | D4: 2 | E4: 3 | F4: 2 | G4: 2 | H4: 2 | I4: 3 | J4: 2 | K4: 3 | L4: 2 | M4: 3 | N4: 2 | O4: 2 | P4: 2 | Q4: 3 | R4: 4 | S4: 2 | T4: 1 | U4: 2 | V4: 2 | W4: 3 | X4: 3 | Y4: 3 | Z4: 5 | AA4: 3 | AB4: 2 | AC4: 4 | AD4: 3 | AE4: 2 | AF4: 2 | AG4: 3 | AH4: 2 | AI4: 2 | AJ4: 2 | AK4: 3 | AL4: 3 | AM4: 2 | AN4: 2 | AO4: 3 | AP4: 4 | AQ4: 4
A5: 41458.936 | B5: idfpower | C5: 2 | D5: 1 | E5: 4 | F5: 1 | G5: 2 | H5: 3 | I5: 3 | J5: 1 | K5: 3 | L5: 2 | M5: 1 | N5: 1 | O5: 5 | P5: 1 | Q5: 2 | R5: 2 | S5: 3 | T5: 1 | U5: 3 | V5: 2 | W5: 1 | X5: 3 | Y5: 2 | Z5: 1 | AA5: 1 | AB5: 2 | AC5: 2 | AD5: 1 | AE5: 1 | AF5: 1 | AG5: 1 | AH5: 2 | AI5: 1 | AJ5: 1 | AK5: 2 | AL5: 3 | AM5: 1 | AN5: 1 | AO5: 1 | AP5: 2 | AQ5: 5
A6: 41458.988 | B6: Irion Da Ronin | C6: 2 | D6: 2 | E6: 4 | F6: 4 | G6: 3 | H6: 4 | I6: 5 | J6: 2 | K6: 4 | L6: 3 | M6: 2 | N6: 4 | O6: 4 | P6: 2 | Q6: 1 | R6: 4 | S6: 4 | T6: 4 | U6: 3 | V6: 3 | W6: 2 | X6: 3 | Y6: 4 | Z6: 3 | AA6: 2 | AB6: 3 | AC6: 5 | AD6: 3 | AE6: 2 | AF6: 2 | AG6: 3 | AH6: 4 | AI6: 2 | AJ6: 2 | AK6: 2 | AL6: 4 | AM6: 2 | AN6: 2 | AO6: 3 | AP6: 4 | AQ6: 4
A7: 41459.049 | B7: LunaTech | C7: 3 | D7: 4 | E7: 4 | F7: 4 | G7: 4 | H7: 4 | I7: 4 | J7: 4 | K7: 4 | L7: 3 | M7: 5 | N7: 4 | O7: 4 | P7: 3 | Q7: 5 | R7: 5 | S7: 4 | T7: 3 | U7: 1 | V7: 4 | W7: 4 | X7: 4 | Y7: 4 | Z7: 3 | AA7: 3 | AB7: 4 | AC7: 4 | AD7: 4 | AE7: 3 | AF7: 4 | AG7: 3 | AH7: 4 | AI7: 4 | AJ7: 3 | AK7: 4 | AL7: 4 | AM7: 4 | AN7: 4 | AO7: 4 | AP7: 4 | AQ7: 5
A8: 41459.371 | B8: ballacr75 revote | C8: 1 | D8: 1 | E8: 5 | F8: 1 | G8: 1 | H8: 3 | I8: 3 | J8: 1 | K8: 1 | L8: 1 | M8: 1 | N8: 1 | O8: 1 | P8: 1 | Q8: 3 | R8: 1 | S8: 3 | T8: 1 | U8: 1 | V8: 5 | W8: 1 | X8: 1 | Y8: 3 | Z8: 1 | AA8: 1 | AB8: 1 | AC8: 1 | AD8: 1 | AE8: 1 | AF8: 1 | AG8: 1 | AH8: 5 | AI8: 1 | AJ8: 1 | AK8: 1 | AL8: 5 | AM8: 1 | AN8: 1 | AO8: 1 | AP8: 5 | AQ8: 5
A9: 41459.786 | B9: RuediRena | C9: 1 | D9: 2 | E9: 4 | F9: 2 | G9: 3 | H9: 5 | I9: 5 | J9: 3 | K9: 4 | L9: 5 | M9: 3 | N9: 4 | O9: 4 | P9: 4 | Q9: 4 | R9: 4 | S9: 5 | T9: 5 | U9: 2 | V9: 5 | W9: 3 | X9: 2 | Y9: 5 | Z9: 1 | AA9: 2 | AB9: 1 | AC9: 3 | AD9: 5 | AE9: 2 | AF9: 3 | AG9: 4 | AH9: 5 | AI9: 3 | AJ9: 4 | AK9: 3 | AL9: 5 | AM9: 3 | AN9: 4 | AO9: 2 | AP9: 3 | AQ9: 5
A10: 41459.989 | B10: Stunkit | C10: 1 | D10: 2 | E10: 4 | F10: 2 | G10: 2 | H10: 5 | I10: 1 | J10: 1 | K10: 2 | L10: 2 | M10: 4 | N10: 2 | O10: 2 | P10: 3 | Q10: 2 | R10: 2 | S10: 2 | T10: 2 | U10: 2 | V10: 2 | W10: 1 | X10: 2 | Y10: 5 | Z10: 2 | AA10: 2 | AB10: 1 | AC10: 3 | AD10: 2 | AE10: 2 | AF10: 4 | AG10: 3 | AH10: 3 | AI10: 2 | AJ10: 1 | AK10: 2 | AL10: 1 | AM10: 2 | AN10: 2 | AO10: 1 | AP10: 2 | AQ10: 5
A11: 41460.808 | B11: SpectralBee | C11: 1 | D11: 2 | E11: 5 | F11: 3 | G11: 4 | H11: 5 | I11: 3 | J11: 2 | K11: 3 | L11: 3 | M11: 4 | N11: 2 | O11: 4 | P11: 3 | Q11: 5 | R11: 4 | S11: 2 | T11: 3 | U11: 3 | V11: 2 | W11: 2 | X11: 3 | Y11: 4 | Z11: 2 | AA11: 1 | AB11: 1 | AC11: 4 | AD11: 2 | AE11: 3 | AF11: 4 | AG11: 4 | AH11: 5 | AI11: 2 | AJ11: 1 | AK11: 1 | AL11: 4 | AM11: 2 | AN11: 3 | AO11: 2 | AP11: 4 | AQ11: 5
A12: 41460.971 | B12: ToneDeF71 | C12: 3 | D12: 3 | E12: 5 | F12: 4 | G12: 3 | H12: 4 | I12: 5 | J12: 3 | K12: 5 | L12: 4 | M12: 4 | N12: 3 | O12: 5 | P12: 3 | Q12: 4 | R12: 4 | S12: 3 | T12: 5 | U12: 3 | V12: 5 | W12: 3 | X12: 4 | Y12: 5 | Z12: 3 | AA12: 3 | AB12: 4 | AC12: 4 | AD12: 3 | AE12: 3 | AF12: 3 | AG12: 3 | AH12: 5 | AI12: 4 | AJ12: 3 | AK12: 3 | AL12: 4 | AM12: 1 | AN12: 4 | AO12: 3 | AP12: 5 | AQ12: 4
A13: 41461.642 | B13: Photonic | C13: 2 | D13: 2 | E13: 4 | F13: 3 | G13: 4 | H13: 5 | I13: 4 | J13: 2 | K13: 5 | L13: 4 | M13: 3 | N13: 2 | O13: 4 | P13: 3 | Q13: 5 | R13: 5 | S13: 5 | T13: 5 | U13: 5 | V13: 3 | W13: 2 | X13: 2 | Y13: 1 | Z13: 2 | AA13: 2 | AB13: 3 | AC13: 3 | AD13: 2 | AE13: 2 | AF13: 4 | AG13: 4 | AH13: 4 | AI13: 2 | AJ13: 3 | AK13: 3 | AL13: 4 | AM13: 4 | AN13: 4 | AO13: 2 | AP13: 5 | AQ13: 5
... A42: 41471.414 | B42: Sonnydeluxe | C42: 1 | D42: 1 | E42: 5 | F42: 2 | G42: 3 | H42: 4 | I42: 3 | J42: 3 | K42: 3 | L42: 2 | M42: 3 | N42: 5 | O42: 3 | P42: 2 | Q42: 4 | R42: 4 | S42: 4 | T42: 1 | U42: 4 | V42: 4 | W42: 3 | X42: 1 | Y42: 3 | Z42: 1 | AA42: 2 | AB42: 2 | AC42: 2 | AD42: 5 | AE42: 5 | AF42: 4 | AG42: 1 | AH42: 3 | AI42: 1 | AJ42: 3 | AK42: 4 | AL42: 4 | AM42: 4 | AN42: 3 | AO42: 4 | AP42: 4 | AQ42: 5

Sheet Form Responses 1
A1: Timestamp | B1: Voter Name | C1: Abovethoughts - To Us.Wavabovethoughts - To Us [Robot Remix] | D1: Ballacr75 - Psyko | E1: Bjporter - Parachuting Down To A Supersaw Welcome | F1: Bjulin - Expedition | G1: Broad Halls Of Yeast - Forlorn Encystment | H1: Bzur - Simple And Clean | I1: Carl Saved - Power, Beauty And Madness | J1: Clarago - Nag | K1: Ctx - Behind The Curtain | L1: Davias - Kvr Osc 53 - Smi -Sft | M1: Dzah - Rainforest | N1: E@rs - The Blade That Shaved Chuck Norris | O1: Evo2slo - Summer Lover | P1: Idfpower - Binary Code | Q1: Irion Da Ronin - Night Walker | R1: Kondarivan - Heat Shield | S1: Kraftraum - Rotation 15 | T1: Kullervo - Stone Alley | U1: Lunatech - Space Phunk Cyber Jazz Session At The Rift Cafe | V1: Mushy Mushy - 60% Crusty | W1: Nikp2000 - There Will Be Pie | X1: Pedalsteeldrummer - Eos | Y1: Photonic - Sound Of Summer Nights | Z1: Quadruplea - Aftermath | AA1: Ricler - On The Road Back To Home | AB1: Ruedirena - Suction V8 | AC1: Saltline - Minas Gerais | AD1: Saukar30 - Breaking Through The Pain | AE1: Simonhans73 - Shake It (Ver. 3) | AF1: Simonhans73- Together (3. Ver) | AG1: Sjmmusic - Sheep Lullaby | AH1: Skyzone - The Albatross Is Eating Plastic | AI1: Sonnydeluxe - Monaco | AJ1: Sovaroz_x0081_m - Journey Through A Panicked Heart | AK1: Spectralbee - One Gun | AL1: Stunkit - Spacefield | AM1: Tonedef71 - Ambush At The Oasis | AN1: Vdx - Falling Stars | AO1: Wakkadude - Saxonite | AP1: Yeager - Paraphrase | AQ1: Z.Prime - Memories
