Workbook

Sheet Voting Results
A1: Timestamp | B1: Voter name (KVR nick) | C1: Alvfaria - To You who have never been here | D1: Arcalium - OSC 50 TAL-U-NO-62 | E1: Askeng - Sunrays | F1: bh9090 - OSCTALUno62_1 | G1: bh9090 - OSCTALUno62_2 | H1: bh9090 - OSCTALUno62_3 | I1: bh9090 - OSCTALUno62_5 | J1: bh9090 - OSCTALUno62_6 | K1: Bjporter - U-NO The Answer | L1: Broad Halls of Yeast - Cold Comfort | M1: Bumtu - Muted Repose | N1: ClaRago - Talisman3 | O1: Dead Eddy - Monotreme | P1: eArs - Ghost In A Box (Part 1) | Q1: Eauson - taluno62 | R1: eraze the borders - Lightwriters | S1: evo2slo - Daughters of Saturn | T1: Farlukar - Catherine | U1: Gamma-ut - Unofortuna | V1: Gorgorgathgorgorgor - Third Rail +3 | W1: Irion Da Ronin - Digital Daydream | X1: Jasinski - Rain or Tears | Y1: Jasinski - Squirrel Assassins | Z1: jsd - U no my name look up the number | AA1: Kenobi77 - Elevator | AB1: Kimik - One Synth Challenge 50 | AC1: liquidgreg - Drowning | AD1: Loris Solic - Digging through trash W.I.P. | AE1: marks-a-whybikky - Unknown Nibbling Object | AF1: moldavsky - Doin' Time | AG1: Nahkaorava - They All Lie | AH1: Nightpolymath - Credo | AI1: Nikp2000 - drifting thoughts | AJ1: Photonic - Fragile | AK1: Quaoar -U-NO What | AL1: Ricler - Little rascals | AM1: RuediRena - Desert Tracks (Haxep 1.3) | AN1: Skyzone - Gelios | AO1: Thrax - MorTALity | AP1: Yeager - The Missing Hour (Part 1) | AQ1: Yeager - The Missing Hour (Part 2)
A2: 41370.055 | B2: bh9090 | K2: 2 | Q2: 4 | X2: 5 | Y2: 3 | AL2: 1
A3: 41370.063 | B3: sergiofrias | D3: 5 | S3: 1 | W3: 4 | Y3: 3 | AQ3: 2
A4: 41370.064 | B4: farlukar | M4: 5 | U4: 1 | X4: 2 | AA4: 4 | AF4: 3
A5: 41370.064 | B5: jasinski | K5: 3 | M5: 4 | S5: 5 | W5: 2 | AG5: 1
A6: 41370.065 | B6: kenobi77 | K6: 4 | M6: 3 | W6: 1 | Y6: 5 | AJ6: 2
A7: 41370.722 | B7: ricler | C7: 2 | I7: 4 | M7: 3 | X7: 5 | AB7: 1
A8: 41370.723 | B8: z.prime | M8: 4 | W8: 3 | Y8: 5 | AB8: 1 | AJ8: 2
A9: 41372.817 | B9: photonic | K9: 3 | W9: 4 | Y9: 2 | AG9: 1 | AP9: 5
A10: 41372.817 | B10: Nightpolymath | K10: 4 | AF10: 2 | AL10: 1 | AO10: 3 | AP10: 5
A11: 41374.041 | B11: eraze the borders | L11: 1 | M11: 3 | S11: 4 | W11: 2 | Y11: 5
A12: 41374.041 | B12: jsd | K12: 2 | M12: 5 | X12: 3 | AB12: 4 | AP12: 1
A13: 41377.78 | B13: loris16148 | K13: 5 | S13: 2 | W13: 4 | Y13: 3 | AO13: 1
A14: 41377.781 | B14: evo2slo | K14: 2 | M14: 4 | Y14: 5 | AE14: 1 | AG14: 3
A15: 41377.781 | B15: nikp2000 | K15: 5 | N15: 1 | S15: 3 | AE15: 4 | AM15: 2
A16: 41378.165 | B16: Gamma-UT | D16: 3 | K16: 4 | S16: 5 | T16: 2 | AB16: 1
A17: 41380.003 | B17: marks-a-whybikky | K17: 1 | M17: 5 | W17: 4 | Y17: 3 | AJ17: 2
A18: 41380.003 | B18: RuediRena | S18: 4 | W18: 2 | Y18: 5 | AD18: 3 | AJ18: 1
A19: 41380.004 | B19: alvfaria | S19: 5 | W19: 2 | Z19: 3 | AE19: 1 | AJ19: 4
A20: 41380.005 | B20: Eauson | M20: 3 | R20: 5 | S20: 1 | X20: 2 | AQ20: 4
A21: 41380.006 | B21: Moldavsky | S21: 1 | W21: 5 | Y21: 3 | AJ21: 4 | AP21: 2
A22: 41380.007 | B22: e@rs | L22: 3 | S22: 5 | W22: 1 | AJ22: 2 | AP22: 4
A23: 41380.007 | B23: bumtu | L23: 2 | S23: 5 | Y23: 4 | AE23: 1 | AJ23: 3
A24: 41380.008 | B24: Yeager | K24: 2 | L24: 1 | M24: 5 | S24: 4 | AJ24: 3
A25: 41380.015 | B25: SKYZONE | K25: 2 | W25: 5 | AJ25: 1 | AM25: 3 | AP25: 4
A26: 41380.016 | B26: ClaRago | I26: 1 | S26: 3 | AB26: 4 | AE26: 5 | AF26: 2
A27: 41380.017 | B27: Thrax | P27: 2 | S27: 1 | W27: 4 | Y27: 3 | AJ27: 5
A28: 41380.044 | B28: bjporter | S28: 1 | W28: 2 | X28: 3 | Y28: 5 | AQ28: 4
A29: 41380.045 | B29: IrionDaRonin | K29: 4 | X29: 1 | AB29: 3 | AJ29: 2 | AP29: 5
A30: 41380.574 | B30: nahkaorava

Sheet TOTAL SCORES
A1: ='Voting Results'!$Y$1 -> Jasinski - Squirrel Assassins | B1: =SUM('Voting Results'!Y1:Y107) -> 54
A2: ='Voting Results'!$S$1 -> evo2slo - Daughters of Saturn | B2: =SUM('Voting Results'!S1:S114) -> 50
A3: ='Voting Results'!$W$1 -> Irion Da Ronin - Digital Daydream | B3: =SUM('Voting Results'!W1:W111) -> 45
A4: ='Voting Results'!$M$1 -> Bumtu - Muted Repose | B4: =SUM('Voting Results'!M1:M121) -> 44
A5: ='Voting Results'!$K$1 -> Bjporter - U-NO The Answer | B5: =SUM('Voting Results'!K1:K124) -> 43
A6: ='Voting Results'!$AJ$1 -> Photonic - Fragile | B6: =SUM('Voting Results'!AJ1:AJ100) -> 31
A7: ='Voting Results'!$AP$1 -> Yeager - The Missing Hour (Part 1) | B7: =SUM('Voting Results'!AP1:AP96) -> 26
A8: ='Voting Results'!$X$1 -> Jasinski - Rain or Tears | B8: =SUM('Voting Results'!X1:X115) -> 21
A9: ='Voting Results'!$AB$1 -> Kimik - One Synth Challenge 50 | B9: =SUM('Voting Results'!AB1:AB112) -> 14
A10: ='Voting Results'!$AE$1 -> marks-a-whybikky - Unknown Nibbling Object | B10: =SUM('Voting Results'!AE1:AE110) -> 12
A11: ='Voting Results'!$AQ$1 -> Yeager - The Missing Hour (Part 2) | B11: =SUM('Voting Results'!AQ1:AQ99) -> 10
A12: ='Voting Results'!$D$1 -> Arcalium - OSC 50 TAL-U-NO-62 | B12: =SUM('Voting Results'!D1:D138) -> 8
A13: ='Voting Results'!$L$1 -> Broad Halls of Yeast - Cold Comfort | B13: =SUM('Voting Results'!L1:L112) -> 7
A14: ='Voting Results'!$AF$1 -> moldavsky - Doin' Time | B14: =SUM('Voting Results'!AF1:AF132) -> 7
A15: ='Voting Results'!$I$1 -> bh9090 - OSCTALUno62_5 | B15: =SUM('Voting Results'!I1:I129) -> 5
A16: ='Voting Results'!$R$1 -> eraze the borders - Lightwriters | B16: =SUM('Voting Results'!R2:R137) -> 5
A17: ='Voting Results'!$AG$1 -> Nahkaorava - They All Lie | B17: =SUM('Voting Results'!AG1:AG114) -> 5
A18: ='Voting Results'!$AM$1 -> RuediRena - Desert Tracks (Haxep 1.3) | B18: =SUM('Voting Results'!AM1:AM109) -> 5
A19: ='Voting Results'!$Q$1 -> Eauson - taluno62 | B19: =SUM('Voting Results'!Q1:Q134) -> 4
A20: ='Voting Results'!$AA$1 -> Kenobi77 - Elevator | B20: =SUM('Voting Results'!AA1:AA124) -> 4
A21: ='Voting Results'!$AO$1 -> Thrax - MorTALity | B21: =SUM('Voting Results'!AO1:AO109) -> 4
A22: ='Voting Results'!$Z$1 -> jsd - U no my name look up the number | B22: =SUM('Voting Results'!Z1:Z127) -> 3
A23: ='Voting Results'!$AD$1 -> Loris Solic - Digging through trash W.I.P. | B23: =SUM('Voting Results'!AD1:AD124) -> 3
A24: ='Voting Results'!$C$1 -> Alvfaria - To You who have never been here | B24: =SUM('Voting Results'!C1:C151) -> 2
A25: ='Voting Results'!$P$1 -> eArs - Ghost In A Box (Part 1) | B25: =SUM('Voting Results'!P1:P138) -> 2
A26: ='Voting Results'!$T$1 -> Farlukar - Catherine | B26: =SUM('Voting Results'!T1:T137) -> 2
A27: ='Voting Results'!$AL$1 -> Ricler - Little rascals | B27: =SUM('Voting Results'!AL1:AL119) -> 2
A28: ='Voting Results'!$N$1 -> ClaRago - Talisman3 | B28: =SUM('Voting Results'!N1:N144) -> 1
A29: ='Voting Results'!$U$1 -> Gamma-ut - Unofortuna | B29: =SUM('Voting Results'!U1:U139) -> 1
A30: ='Voting Results'!$E$1 -> Askeng - Sunrays | B30: =SUM('Voting Results'!E1:E155) -> 0
A31: ='Voting Results'!$F$1 -> bh9090 - OSCTALUno62_1 | B31: =SUM('Voting Results'!F1:F155) -> 0
A32: ='Voting Results'!$G$1 -> bh9090 - OSCTALUno62_2 | B32: =SUM('Voting Results'!G1:G155) -> 0
A33: ='Voting Results'!$H$1 -> bh9090 - OSCTALUno62_3 | B33: =SUM('Voting Results'!H1:H155) -> 0
A34: ='Voting Results'!$J$1 -> bh9090 - OSCTALUno62_6 | B34: =SUM('Voting Results'!J1:J154) -> 0
A35: ='Voting Results'!$O$1 -> Dead Eddy - Monotreme | B35: =SUM('Voting Results'!O1:O150) -> 0
A36: ='Voting Results'!$V$1 -> Gorgorgathgorgorgor - Third Rail +3 | B36: =SUM('Voting Results'!V1:V145) -> 0
A37: ='Voting Results'!$AC$1 -> liquidgreg - Drowning | B37: =SUM('Voting Results'!AC1:AC139) -> 0
A38: ='Voting Results'!$AH$1 -> Nightpolymath - Credo | B38: =SUM('Voting Results'!AH1:AH134) -> 0
A39: ='Voting Results'!$AI$1 -> Nikp2000 - drifting thoughts | B39: =SUM('Voting Results'!AI1:AI134) -> 0
A40: ='Voting Results'!$AK$1 -> Quaoar -U-NO What | B40: =SUM('Voting Results'!AK1:AK133) -> 0
...
