Workbook

Sheet Voting Results
A1: Timestamp | B1: Voter name: | C1: Acronym - Itz Halftim3 | D1: adam_firegate - Microns | E1: adam_firegate - Pasadena | F1: adam_firegate - Shivers | G1: Akson - Free Canned Sardines | H1: Alphuris - 8 Weeks til Vegas | I1: Alphuris - Bad Kidney | J1: Alphuris - Safari Cruise | K1: Andjac1963 - Savannah Gold | L1: Andjac1963 - Stripes in Bb | M1: Bzur - drunkZebra | N1: Bzur - Kepler-12b | O1: Bzur - Virgo's eyes | P1: Doc Jon - Iona Sunrise | Q1: DP - Are We Alone | R1: Evo2slo - Earn Your Stripes | S1: Evo2slo - Zebralove | T1: Examigan - Nebula | U1: Flumba - Grumpy-Bot Accidentally Grows Wings | V1: Gigue07 - Syntheza-x | W1: Gorgorgathgorgorgor - Android Holiday mix2 | X1: IrionDaRonin - Asian Passion | Y1: IrionDaRonin - Beautiful Electronic Creature | Z1: Joe Cat - Chasing Mrs. Peel | AA1: Kalee - Society of forest lemmings | AB1: Marsar - Constant theory | AC1: Marks-a-whybikky - smoking a zebralette | AD1: Mrblitz000 - Walter and Walter | AE1: Mr Blitz - Walter and Walter Redux | AF1: Petedako - Moonlit Zebralette | AG1: Painpotato - Redshift | AH1: RuediRena - Heqman Jah | AI1: RuediRena - Night Of The Living Zebra | AJ1: SatYatunes - Aurora | AK1: The zebralette, the frog and the clarinette - ? | AL1: Vanmorrison - All My Love | AM1: Ville - Precog Dreamer | AN1: Yeager - Zebraskie Point | AO1: Z.prime - I, You | AP1: entry 2 name here etc | AQ1: 4lb Kitty - Alone | AR1: Ancient - Ice Cream Summer
A2: 40819.867 | B2: Lotuzia | O2: 5 | P2: 4 | Z2: 3 | AA2: 1 | AL2: 2
A3: 40819.867 | B3: adam_firegate | U3: 5 | V3: 2 | AB3: 4 | AL3: 3 | AQ3: 1
A4: 40819.868 | B4: gigue07 | O4: 4 | P4: 2 | X4: 3 | AL4: 1 | AO4: 5
A5: 40819.868 | B5: alphuris | O5: 4 | P5: 2 | R5: 3 | U5: 1
A6: 40819.872 | B6: Doc Jon | N6: 2 | U6: 1 | Y6: 3 | Z6: 4 | AR6: 5
A7: 40819.873 | B7: Examigan | O7: 5 | P7: 2 | S7: 4 | Y7: 3 | AF7: 1
A8: 40819.873 | B8: z.prime | O8: 4 | P8: 3 | V8: 2 | X8: 5 | AM8: 1
A9: 40819.875 | B9: andjac1963 | G9: 4 | R9: 1 | U9: 3 | Z9: 5 | AR9: 2
A10: 40820.672 | B10: Acronym | G10: 4 | R10: 5 | X10: 2 | Z10: 3 | AM10: 1
A11: 40820.673 | B11: akson | O11: 3 | P11: 2 | Z11: 4 | AM11: 1 | AR11: 5
A12: 40822.633 | B12: Kalee | M12: 3 | P12: 2 | R12: 1 | X12: 4 | AR12: 5
A13: 40823.883 | B13: GMoneh | M13: 5 | AJ13: 4 | AN13: 1 | AO13: 3 | AR13: 2
A14: 40830.59 | B14: RuediRena | S14: 2 | AE14: 1 | AJ14: 4 | AL14: 5 | AN14: 3
A15: 40830.591 | B15: ville | O15: 3 | S15: 5 | AF15: 1 | AO15: 2 | AR15: 4
A16: 40830.592 | B16: Doomedman | E16: 1 | O16: 5 | V16: 3 | Y16: 4 | AJ16: 2
A17: 40831.149 | B17: Ancient | G17: 2 | M17: 1 | X17: 4 | AA17: 5 | AL17: 3
A18: 40831.149 | B18: Yeager | G18: 5 | M18: 3 | P18: 1 | Y18: 2 | Z18: 4
A19: 40831.159 | B19: Bzur | P19: 5 | R19: 2 | V19: 4 | AM19: 1 | AR19: 3
A20: 40831.16 | B20: hakey | G20: 1 | P20: 4 | Y20: 5 | AN20: 3 | AR20: 2
A21: 40831.161 | B21: SJMmusic | M21: 2 | P21: 5 | X21: 1 | AQ21: 3 | AR21: 4
A22: 40831.162 | B22: evo2slo | M22: 3 | P22: 5 | Z22: 1 | AM22: 4 | AR22: 2
A23: 40831.162 | B23: flumba | O23: 4 | P23: 1 | Y23: 2 | AM23: 5 | AN23: 3
A24: 40831.163 | B24: satYatunes | O24: 4 | P24: 2 | X24: 3 | AO24: 1 | AR24: 5
A25: 40831.564 | B25: IrionDaRonin | K25: 1 | O25: 2 | U25: 5 | AL25: 4 | AO25: 3
A26: 40831.769 | B26: JoeCat | G26: 3 | P26: 2 | U26: 1 | AM26: 4 | AR26: 5
A27: 40832.505 | B27: 3ee | O27: 4 | P27: 3 | Y27: 1 | AA27: 5 | AR27: 2
A28: 40832.506 | B28: Guenon | G28: 1 | O28: 2 | U28: 5 | Y28: 3 | AM28: 4

Sheet TOTAL SCORES
A1: ='Voting Results'!$O$1 -> Bzur - Virgo's eyes | B1: =SUM('Voting Results'!O1:O114) -> 49
A2: ='Voting Results'!$AR$1 -> Ancient - Ice Cream Summer | B2: =SUM('Voting Results'!AR1:AR87) -> 46
A3: ='Voting Results'!$P$1 -> Doc Jon - Iona Sunrise | B3: =SUM('Voting Results'!P1:P115) -> 45
A4: ='Voting Results'!$Z$1 -> Joe Cat - Chasing Mrs. Peel | B4: =SUM('Voting Results'!Z1:Z106) -> 24
A5: ='Voting Results'!$Y$1 -> IrionDaRonin - Beautiful Electronic Creature | B5: =SUM('Voting Results'!Y1:Y108) -> 23
A6: ='Voting Results'!$X$1 -> IrionDaRonin - Asian Passion | B6: =SUM('Voting Results'!X1:X110) -> 22
A7: ='Voting Results'!$U$1 -> Flumba - Grumpy-Bot Accidentally Grows Wings | B7: =SUM('Voting Results'!U1:U114) -> 21
A8: ='Voting Results'!$AM$1 -> Ville - Precog Dreamer | B8: =SUM('Voting Results'!AM1:AM97) -> 21
A9: ='Voting Results'!$G$1 -> Akson - Free Canned Sardines | B9: =SUM('Voting Results'!G1:G130) -> 20
A10: ='Voting Results'!$AL$1 -> Vanmorrison - All My Love | B10: =SUM('Voting Results'!AL1:AL100) -> 18
A11: ='Voting Results'!$M$1 -> Bzur - drunkZebra | B11: =SUM('Voting Results'!M1:M126) -> 17
A12: ='Voting Results'!$AO$1 -> Z.prime - I, You | B12: =SUM('Voting Results'!AO1:AO99) -> 14
A13: ='Voting Results'!$R$1 -> Evo2slo - Earn Your Stripes | B13: =SUM('Voting Results'!R1:R123) -> 12
A14: ='Voting Results'!$AA$1 -> Kalee - Society of forest lemmings | B14: =SUM('Voting Results'!S1:S123) -> 11
A15: ='Voting Results'!$V$1 -> Gigue07 - Syntheza-x | B15: =SUM('Voting Results'!V1:V121) -> 11
A16: ='Voting Results'!$S$1 -> Evo2slo - Zebralove | B16: =SUM('Voting Results'!AA1:AA117) -> 11
A17: ='Voting Results'!$AJ$1 -> SatYatunes - Aurora | B17: =SUM('Voting Results'!AJ1:AJ109) -> 10
A18: ='Voting Results'!$AN$1 -> Yeager - Zebraskie Point | B18: =SUM('Voting Results'!AN1:AN106) -> 10
A19: ='Voting Results'!$AB$1 -> Marsar - Constant theory | B19: =SUM('Voting Results'!AB1:AB119) -> 4
A20: ='Voting Results'!$AQ$1 -> 4lb Kitty - Alone | B20: =SUM('Voting Results'!AQ1:AQ106) -> 4
A21: ='Voting Results'!$N$1 -> Bzur - Kepler-12b | B21: =SUM('Voting Results'!N1:N135) -> 2
A22: ='Voting Results'!$AF$1 -> Petedako - Moonlit Zebralette | B22: =SUM('Voting Results'!AF1:AF118) -> 2
A23: ='Voting Results'!$E$1 -> adam_firegate - Pasadena | B23: =SUM('Voting Results'!E1:E146) -> 1
A24: ='Voting Results'!$K$1 -> Andjac1963 - Savannah Gold | B24: =SUM('Voting Results'!K1:K141) -> 1
A25: ='Voting Results'!$AE$1 -> Mr Blitz - Walter and Walter Redux | B25: =SUM('Voting Results'!AE1:AE122) -> 1
A26: ='Voting Results'!$C$1 -> Acronym - Itz Halftim3 | B26: =SUM('Voting Results'!C1:C151) -> 0
A27: ='Voting Results'!$D$1 -> adam_firegate - Microns | B27: =SUM('Voting Results'!D1:D151) -> 0
A28: ='Voting Results'!$F$1 -> adam_firegate - Shivers | B28: =SUM('Voting Results'!F1:F150) -> 0
A29: ='Voting Results'!$H$1 -> Alphuris - 8 Weeks til Vegas | B29: =SUM('Voting Results'!H1:H149) -> 0
A30: ='Voting Results'!$I$1 -> Alphuris - Bad Kidney | B30: =SUM('Voting Results'!I1:I149) -> 0
A31: ='Voting Results'!$J$1 -> Alphuris - Safari Cruise | B31: =SUM('Voting Results'!J1:J149) -> 0
A32: ='Voting Results'!$L$1 -> Andjac1963 - Stripes in Bb | B32: =SUM('Voting Results'!L1:L148) -> 0
A33: ='Voting Results'!$Q$1 -> DP - Are We Alone | B33: =SUM('Voting Results'!Q1:Q144) -> 0
A34: ='Voting Results'!$T$1 -> Examigan - Nebula | B34: =SUM('Voting Results'!T1:T142) -> 0
A35: ='Voting Results'!$W$1 -> Gorgorgathgorgorgor - Android Holiday mix2 | B35: =SUM('Voting Results'!W1:W140) -> 0
A36: ='Voting Results'!$AC$1 -> Marks-a-whybikky - smoking a zebralette | B36: =SUM('Voting Results'!AC1:AC135) -> 0
A37: ='Voting Results'!$AD$1 -> Mrblitz000 - Walter and Walter | B37: =SUM('Voting Results'!AD1:AD135) -> 0
A38: ='Voting Results'!$AG$1 -> Painpotato - Redshift | B38: =SUM('Voting Results'!AG1:AG133) -> 0
A39: ='Voting Results'!$AH$1 -> RuediRena - Heqman Jah | B39: =SUM('Voting Results'!AH1:AH133) -> 0
A40: ='Voting Results'!$AI$1 -> RuediRena - Night Of The Living Zebra | B40: =SUM('Voting Results'!AI1:AI133) -> 0
...
